------ MEMORY MANAGEMENT TEST 0 ------------------------------------
./mem input/proc/m0
000: 00000-003ff - PID: 01 (idx 017, nxt: 001)
	003e8: 15
001: 00400-007ff - PID: 01 (idx 018, nxt: -01)
002: 00800-00bff - PID: 01 (idx 019, nxt: 003)
003: 00c00-00fff - PID: 01 (idx 020, nxt: 004)
004: 01000-013ff - PID: 01 (idx 021, nxt: 005)
005: 01400-017ff - PID: 01 (idx 022, nxt: 006)
006: 01800-01bff - PID: 01 (idx 023, nxt: -01)
014: 03800-03bff - PID: 01 (idx 015, nxt: 015)
	03814: 66
015: 03c00-03fff - PID: 01 (idx 016, nxt: -01)
NOTE: Read file output/m0 to verify your result
------ MEMORY MANAGEMENT TEST 1 ------------------------------------
./mem input/proc/m1
NOTE: Read file output/m1 to verify your result (your implementation should print nothing)
------ SCHEDULING TEST 0 -------------------------------------------
./os sched_0
Time slot   0
	Loaded a process at input/proc/s0, PID: 1
Time slot   1
	CPU 0: Dispatched process  1
Time slot   2
Time slot   3
	CPU 0: Put process  1 to run queue
	CPU 0: Dispatched process  1
Time slot   4
	Loaded a process at input/proc/s1, PID: 2
Time slot   5
	CPU 0: Put process  1 to run queue
	CPU 0: Dispatched process  2
Time slot   6
Time slot   7
	CPU 0: Put process  2 to run queue
	CPU 0: Dispatched process  2
Time slot   8
Time slot   9
	CPU 0: Put process  2 to run queue
	CPU 0: Dispatched process  1
Time slot  10
Time slot  11
	CPU 0: Put process  1 to run queue
	CPU 0: Dispatched process  2
Time slot  12
Time slot  13
	CPU 0: Put process  2 to run queue
	CPU 0: Dispatched process  1
Time slot  14
Time slot  15
	CPU 0: Put process  1 to run queue
	CPU 0: Dispatched process  2
Time slot  16
	CPU 0: Processed  2 has finished
	CPU 0: Dispatched process  1
Time slot  17
Time slot  18
	CPU 0: Put process  1 to run queue
	CPU 0: Dispatched process  1
Time slot  19
Time slot  20
	CPU 0: Put process  1 to run queue
	CPU 0: Dispatched process  1
Time slot  21
Time slot  22
	CPU 0: Put process  1 to run queue
	CPU 0: Dispatched process  1
Time slot  23
	CPU 0: Processed  1 has finished
	CPU 0 stopped

MEMORY CONTENT: 
NOTE: Read file output/sched_0 to verify your result
------ SCHEDULING TEST 1 -------------------------------------------
./os sched_1
Time slot   0
	Loaded a process at input/proc/s0, PID: 1
Time slot   1
	CPU 0: Dispatched process  1
Time slot   2
Time slot   3
	CPU 0: Put process  1 to run queue
	CPU 0: Dispatched process  1
Time slot   4
	Loaded a process at input/proc/s1, PID: 2
Time slot   5
	CPU 0: Put process  1 to run queue
	CPU 0: Dispatched process  2
Time slot   6
	Loaded a process at input/proc/s2, PID: 3
Time slot   7
	CPU 0: Put process  2 to run queue
	CPU 0: Dispatched process  3
	Loaded a process at input/proc/s3, PID: 4
Time slot   8
Time slot   9
	CPU 0: Put process  3 to run queue
	CPU 0: Dispatched process  4
Time slot  10
Time slot  11
	CPU 0: Put process  4 to run queue
	CPU 0: Dispatched process  2
Time slot  12
Time slot  13
	CPU 0: Put process  2 to run queue
	CPU 0: Dispatched process  3
Time slot  14
Time slot  15
	CPU 0: Put process  3 to run queue
	CPU 0: Dispatched process  1
Time slot  16
Time slot  17
	CPU 0: Put process  1 to run queue
	CPU 0: Dispatched process  4
Time slot  18
Time slot  19
	CPU 0: Put process  4 to run queue
	CPU 0: Dispatched process  2
Time slot  20
Time slot  21
	CPU 0: Put process  2 to run queue
	CPU 0: Dispatched process  3
Time slot  22
Time slot  23
	CPU 0: Put process  3 to run queue
	CPU 0: Dispatched process  1
Time slot  24
Time slot  25
	CPU 0: Put process  1 to run queue
	CPU 0: Dispatched process  4
Time slot  26
Time slot  27
	CPU 0: Put process  4 to run queue
	CPU 0: Dispatched process  2
Time slot  28
	CPU 0: Processed  2 has finished
	CPU 0: Dispatched process  3
Time slot  29
Time slot  30
	CPU 0: Put process  3 to run queue
	CPU 0: Dispatched process  1
Time slot  31
Time slot  32
	CPU 0: Put process  1 to run queue
	CPU 0: Dispatched process  4
Time slot  33
Time slot  34
	CPU 0: Put process  4 to run queue
	CPU 0: Dispatched process  3
Time slot  35
Time slot  36
	CPU 0: Put process  3 to run queue
	CPU 0: Dispatched process  1
Time slot  37
Time slot  38
	CPU 0: Put process  1 to run queue
	CPU 0: Dispatched process  4
Time slot  39
Time slot  40
	CPU 0: Put process  4 to run queue
	CPU 0: Dispatched process  3
Time slot  41
Time slot  42
	CPU 0: Processed  3 has finished
	CPU 0: Dispatched process  1
Time slot  43
Time slot  44
	CPU 0: Put process  1 to run queue
	CPU 0: Dispatched process  4
Time slot  45
	CPU 0: Processed  4 has finished
	CPU 0: Dispatched process  1
Time slot  46
	CPU 0: Processed  1 has finished
	CPU 0 stopped

MEMORY CONTENT: 
NOTE: Read file output/sched_1 to verify your result
----- OS TEST 0 ----------------------------------------------------
./os os_0
Time slot   0
	Loaded a process at input/proc/p0, PID: 1
	CPU 1: Dispatched process  1
Time slot   1
Time slot   2
	Loaded a process at input/proc/p1, PID: 2
	CPU 0: Dispatched process  2
Time slot   3
	Loaded a process at input/proc/p1, PID: 3
Time slot   4
	Loaded a process at input/proc/p1, PID: 4
Time slot   5
Time slot   6
	CPU 1: Put process  1 to run queue
	CPU 1: Dispatched process  3
Time slot   7
Time slot   8
	CPU 0: Put process  2 to run queue
	CPU 0: Dispatched process  4
Time slot   9
Time slot  10
Time slot  11
Time slot  12
	CPU 1: Put process  3 to run queue
	CPU 1: Dispatched process  1
Time slot  13
Time slot  14
	CPU 0: Put process  4 to run queue
	CPU 0: Dispatched process  2
Time slot  15
Time slot  16
	CPU 1: Processed  1 has finished
	CPU 1: Dispatched process  3
Time slot  17
Time slot  18
	CPU 0: Processed  2 has finished
	CPU 0: Dispatched process  4
Time slot  19
Time slot  20
	CPU 1: Processed  3 has finished
	CPU 1 stopped
Time slot  21
Time slot  22
	CPU 0: Processed  4 has finished
	CPU 0 stopped

MEMORY CONTENT: 
000: 00000-003ff - PID: 03 (idx 047, nxt: 001)
001: 00400-007ff - PID: 03 (idx 048, nxt: 006)
002: 00800-00bff - PID: 02 (idx 047, nxt: 003)
003: 00c00-00fff - PID: 02 (idx 048, nxt: 004)
004: 01000-013ff - PID: 02 (idx 049, nxt: 005)
005: 01400-017ff - PID: 02 (idx 050, nxt: -01)
006: 01800-01bff - PID: 03 (idx 049, nxt: 012)
007: 01c00-01fff - PID: 02 (idx 001, nxt: 008)
008: 02000-023ff - PID: 02 (idx 002, nxt: 009)
009: 02400-027ff - PID: 02 (idx 003, nxt: 010)
	025e7: 0a
010: 02800-02bff - PID: 02 (idx 004, nxt: 011)
011: 02c00-02fff - PID: 02 (idx 005, nxt: -01)
012: 03000-033ff - PID: 03 (idx 050, nxt: -01)
013: 03400-037ff - PID: 04 (idx 047, nxt: 028)
014: 03800-03bff - PID: 03 (idx 001, nxt: 015)
015: 03c00-03fff - PID: 03 (idx 002, nxt: 016)
016: 04000-043ff - PID: 03 (idx 003, nxt: 017)
	041e7: 0a
017: 04400-047ff - PID: 03 (idx 004, nxt: 018)
018: 04800-04bff - PID: 03 (idx 005, nxt: -01)
019: 04c00-04fff - PID: 04 (idx 001, nxt: 020)
020: 05000-053ff - PID: 04 (idx 002, nxt: 021)
021: 05400-057ff - PID: 04 (idx 003, nxt: 022)
	055e7: 0a
022: 05800-05bff - PID: 04 (idx 004, nxt: 023)
023: 05c00-05fff - PID: 04 (idx 005, nxt: -01)
028: 07000-073ff - PID: 04 (idx 048, nxt: 029)
029: 07400-077ff - PID: 04 (idx 049, nxt: 030)
030: 07800-07bff - PID: 04 (idx 050, nxt: -01)
047: 0bc00-0bfff - PID: 01 (idx 008, nxt: -01)
	0bc14: 64
NOTE: Read file output/os_0 to verify your result
----- OS TEST 1 ----------------------------------------------------
./os os_1
Time slot   0
Time slot   1
	Loaded a process at input/proc/p0, PID: 1
	CPU 0: Dispatched process  1
Time slot   2
	Loaded a process at input/proc/s3, PID: 2
Time slot   3
	CPU 0: Put process  1 to run queue
	CPU 0: Dispatched process  2
	CPU 3: Dispatched process  1
Time slot   4
	Loaded a process at input/proc/m1, PID: 3
	CPU 2: Dispatched process  3
Time slot   5
	CPU 0: Put process  2 to run queue
	CPU 0: Dispatched process  2
	CPU 3: Put process  1 to run queue
	CPU 3: Dispatched process  1
Time slot   6
	Loaded a process at input/proc/s2, PID: 4
	CPU 2: Put process  3 to run queue
	CPU 2: Dispatched process  4
Time slot   7
	CPU 0: Put process  2 to run queue
	CPU 0: Dispatched process  2
	CPU 3: Put process  1 to run queue
	CPU 3: Dispatched process  3
	CPU 1: Dispatched process  1
	Loaded a process at input/proc/m0, PID: 5
Time slot   8
	CPU 2: Put process  4 to run queue
	CPU 2: Dispatched process  5
Time slot   9
	Loaded a process at input/proc/p1, PID: 6
	CPU 3: Put process  3 to run queue
	CPU 1: Put process  1 to run queue
	CPU 1: Dispatched process  4
	CPU 0: Put process  2 to run queue
	CPU 0: Dispatched process  3
	CPU 3: Dispatched process  6
Time slot  10
	CPU 2: Put process  5 to run queue
	CPU 2: Dispatched process  1
Time slot  11
	Loaded a process at input/proc/s0, PID: 7
	CPU 3: Put process  6 to run queue
	CPU 0: Put process  3 to run queue
	CPU 1: Put process  4 to run queue
	CPU 0: Dispatched process  2
	CPU 1: Dispatched process  5
	CPU 3: Dispatched process  7
Time slot  12
	CPU 2: Processed  1 has finished
	CPU 2: Dispatched process  6
Time slot  13
	CPU 3: Put process  7 to run queue
	CPU 3: Dispatched process  3
	CPU 1: Put process  5 to run queue
	CPU 0: Put process  2 to run queue
	CPU 0: Dispatched process  7
	CPU 1: Dispatched process  4
Time slot  14
	CPU 2: Put process  6 to run queue
	CPU 2: Dispatched process  5
Time slot  15
	CPU 0: Put process  7 to run queue
	CPU 3: Processed  3 has finished
	CPU 0: Dispatched process  7
	CPU 3: Dispatched process  2
	CPU 1: Put process  4 to run queue
	CPU 1: Dispatched process  6
Time slot  16
	Loaded a process at input/proc/s1, PID: 8
	CPU 2: Put process  5 to run queue
	CPU 2: Dispatched process  8
Time slot  17
	CPU 3: Put process  2 to run queue
	CPU 1: Put process  6 to run queue
	CPU 0: Put process  7 to run queue
	CPU 0: Dispatched process  2
	CPU 1: Dispatched process  5
	CPU 3: Dispatched process  4
Time slot  18
	CPU 2: Put process  8 to run queue
	CPU 2: Dispatched process  8
	CPU 1: Processed  5 has finished
	CPU 0: Processed  2 has finished
	CPU 0: Dispatched process  6
	CPU 1: Dispatched process  7
Time slot  19
	CPU 3: Put process  4 to run queue
	CPU 3: Dispatched process  4
Time slot  20
	CPU 2: Put process  8 to run queue
	CPU 2: Dispatched process  8
	CPU 0: Put process  6 to run queue
	CPU 1: Put process  7 to run queue
	CPU 0: Dispatched process  6
	CPU 1: Dispatched process  7
Time slot  21
	CPU 3: Put process  4 to run queue
	CPU 3: Dispatched process  4
Time slot  22
	CPU 2: Put process  8 to run queue
	CPU 2: Dispatched process  8
	CPU 1: Put process  7 to run queue
	CPU 1: Dispatched process  7
	CPU 0: Processed  6 has finished
	CPU 0 stopped
Time slot  23
	CPU 3: Processed  4 has finished
	CPU 3 stopped
	CPU 2: Processed  8 has finished
	CPU 2 stopped
Time slot  24
	CPU 1: Put process  7 to run queue
	CPU 1: Dispatched process  7
Time slot  25
Time slot  26
	CPU 1: Put process  7 to run queue
	CPU 1: Dispatched process  7
Time slot  27
	CPU 1: Processed  7 has finished
	CPU 1 stopped

MEMORY CONTENT: 
000: 00000-003ff - PID: 05 (idx 017, nxt: 001)
	003e8: 15
001: 00400-007ff - PID: 05 (idx 018, nxt: -01)
002: 00800-00bff - PID: 05 (idx 019, nxt: 003)
003: 00c00-00fff - PID: 05 (idx 020, nxt: 004)
004: 01000-013ff - PID: 05 (idx 021, nxt: 005)
005: 01400-017ff - PID: 05 (idx 022, nxt: 006)
006: 01800-01bff - PID: 05 (idx 023, nxt: -01)
011: 02c00-02fff - PID: 06 (idx 047, nxt: 012)
012: 03000-033ff - PID: 06 (idx 048, nxt: 013)
013: 03400-037ff - PID: 06 (idx 049, nxt: 014)
014: 03800-03bff - PID: 06 (idx 050, nxt: -01)
019: 04c00-04fff - PID: 01 (idx 008, nxt: -01)
	04c14: 64
024: 06000-063ff - PID: 05 (idx 015, nxt: 025)
	06014: 66
025: 06400-067ff - PID: 05 (idx 016, nxt: -01)
031: 07c00-07fff - PID: 06 (idx 001, nxt: 032)
032: 08000-083ff - PID: 06 (idx 002, nxt: 033)
033: 08400-087ff - PID: 06 (idx 003, nxt: 034)
	085e7: 0a
034: 08800-08bff - PID: 06 (idx 004, nxt: 035)
035: 08c00-08fff - PID: 06 (idx 005, nxt: -01)
NOTE: Read file output/os_1 to verify your result
